Workbook

Sheet Comparison Graphs
A1: Comparisons

Sheet Mode 0
A1: N | B1: Mode | C1: Threads | D1: Schedule | E1: Time 1 | F1: Time 2 | G1: Time 3 | H1: Time 4 | I1: Time 5 | J1: Time 6 | K1: Time 7 | L1: Time 8 | M1: Time 9 | N1: Time 10 | O1: AverageTime
A2: 512 | B2: 0 | C2: 1 | E2: 0.21995 | F2: 0.23585 | G2: 0.227252 | H2: 0.226399 | I2: 0.233919 | J2: 0.242686 | K2: 0.227238 | L2: 0.235145 | M2: 0.226741 | N2: 0.233797 | O2: =AVERAGE(D2:N2) -> 0.2308977
A3: 1024 | B3: 0 | C3: 1 | E3: 1.850986 | F3: 1.8522 | G3: 1.843411 | H3: 1.840387 | I3: 1.84881 | J3: 1.850335 | K3: 1.89099 | L3: 1.859111 | M3: 1.835427 | N3: 1.86033 | O3: =AVERAGE(D3:N3) -> 1.8531987
A4: 2048 | B4: 0 | C4: 1 | E4: 45.97532 | F4: 47.982635 | G4: 47.254229 | H4: 46.530127 | I4: 49.692846 | J4: 47.546797 | K4: 48.967996 | L4: 49.292816 | M4: 46.314854 | N4: 48.034902 | O4: =AVERAGE(D4:N4) -> 47.759252

Sheet Mode 1
A1: N | B1: Mode | C1: Threads | D1: Schedule | E1: Time 1 | F1: Time 2 | G1: Time 3 | H1: Time 4 | I1: Time 5 | J1: Time 6 | K1: Time 7 | L1: Time 8 | M1: Time 9 | N1: Time 10 | O1: AverageTime | Q1: Speedup | R1: Efficiency (%)
A2: 512 | B2: 1 | C2: 1 | D2: static | E2: 0.238677 | F2: 0.228328 | G2: 0.231977 | H2: 0.229795 | I2: 0.230082 | J2: 0.223667 | K2: 0.23261 | L2: 0.221115 | M2: 0.229285 | N2: 0.232248 | O2: =AVERAGE(D2:N2) -> 0.2297784 | Q2: =(('Mode 0'!O2)/(O2)) -> 1.0048712 | R2: =_xlfn.PERCENTOF(Q2,C2)*100 -> 100.48712
A3: 1024 | B3: 1 | C3: 1 | D3: static | E3: 1.847531 | F3: 1.858355 | G3: 1.847744 | H3: 1.860858 | I3: 1.863674 | J3: 1.857445 | K3: 1.852507 | L3: 1.858663 | M3: 1.854072 | N3: 1.870014 | O3: =AVERAGE(D3:N3) -> 1.8570863 | Q3: =(('Mode 0'!O3)/(O3)) -> 0.99790661 | R3: =_xlfn.PERCENTOF(Q3,C3)*100 -> 99.790661
A4: 2048 | B4: 1 | C4: 1 | D4: static | E4: 44.956354 | F4: 47.282966 | G4: 45.812847 | H4: 46.580613 | I4: 49.065679 | J4: 47.630266 | K4: 46.629286 | L4: 46.284743 | M4: 50.174486 | N4: 48.596951 | O4: =AVERAGE(D4:N4) -> 47.301419 | Q4: =(('Mode 0'!O4)/(O4)) -> 1.0096791 | R4: =_xlfn.PERCENTOF(Q4,C4)*100 -> 100.96791
A6: 512 | B6: 1 | C6: 2 | D6: static | E6: 0.120597 | F6: 0.121762 | G6: 0.118838 | H6: 0.119326 | I6: 0.119954 | J6: 0.119334 | K6: 0.123882 | L6: 0.123275 | M6: 0.115563 | N6: 0.122993 | O6: =AVERAGE(D6:N6) -> 0.1205524 | Q6: =(('Mode 0'!O2)/(O6)) -> 1.9153306 | R6: =_xlfn.PERCENTOF(Q6,C6)*100 -> 95.76653
A7: 1024 | B7: 1 | C7: 2 | D7: static | E7: 1.007686 | F7: 0.979063 | G7: 1.010601 | H7: 0.970532 | I7: 0.999428 | J7: 0.988326 | K7: 1.009407 | L7: 1.00981 | M7: 1.01145 | N7: 1.015531 | O7: =AVERAGE(D7:N7) -> 1.0001834 | Q7: =(('Mode 0'!O3)/(O7)) -> 1.8528589 | R7: =_xlfn.PERCENTOF(Q7,C7)*100 -> 92.642944
A8: 2048 | B8: 1 | C8: 2 | D8: static | E8: 28.525129 | F8: 29.17164 | G8: 29.000758 | H8: 29.133234 | I8: 27.833344 | J8: 28.508322 | K8: 27.604971 | L8: 30.397101 | M8: 27.760205 | N8: 30.029766 | O8: =AVERAGE(D8:N8) -> 28.796447 | Q8: =(('Mode 0'!O4)/(O8)) -> 1.658512 | R8: =_xlfn.PERCENTOF(Q8,C8)*100 -> 82.925599
A10: 512 | B10: 1 | C10: 4 | D10: static | E10: 0.066894 | F10: 0.065104 | G10: 0.066444 | H10: 0.068694 | I10: 0.063834 | J10: 0.064747 | K10: 0.067076 | L10: 0.063856 | M10: 0.065496 | N10: 0.077736 | O10: =AVERAGE(D10:N10) -> 0.0669881 | Q10: =(('Mode 0'!O2)/(O10)) -> 3.4468465 | R10: =_xlfn.PERCENTOF(Q10,C10)*100 -> 86.171163
A11: 1024 | B11: 1 | C11: 4 | D11: static | E11: 0.528652 | F11: 0.512821 | G11: 0.52872 | H11: 0.527773 | I11: 0.53657 | J11: 0.518769 | K11: 0.529508 | L11: 0.505749 | M11: 0.525112 | N11: 0.521706 | O11: =AVERAGE(D11:N11) -> 0.523538 | Q11: =(('Mode 0'!O3)/(O11)) -> 3.5397597 | R11: =_xlfn.PERCENTOF(Q11,C11)*100 -> 88.493992
A12: 2048 | B12: 1 | C12: 4 | D12: static | E12: 11.510987 | F12: 10.721017 | G12: 11.667309 | H12: 10.760125 | I12: 11.330572 | J12: 10.838474 | K12: 10.70659 | L12: 13.811587 | M12: 10.947552 | N12: 10.866992 | O12: =AVERAGE(D12:N12) -> 11.316121 | Q12: =(('Mode 0'!O4)/(O12)) -> 4.2204616 | R12: =_xlfn.PERCENTOF(Q12,C12)*100 -> 105.51154
A14: 512 | B14: 1 | C14: 8 | D14: static | E14: 0.036061 | F14: 0.035774 | G14: 0.03742 | H14: 0.035871 | I14: 0.034547 | J14: 0.050682 | K14: 0.035779 | L14: 0.036491 | M14: 0.043524 | N14: 0.045649 | O14: =AVERAGE(D14:N14) -> 0.0391798 | Q14: =(('Mode 0'!O2)/(O14)) -> 5.8932843 | R14: =_xlfn.PERCENTOF(Q14,C14)*100 -> 73.666054
A15: 1024 | B15: 1 | C15: 8 | D15: static | E15: 0.27963 | F15: 0.30045 | G15: 0.279928 | H15: 0.282698 | I15: 0.286546 | J15: 0.281716 | K15: 0.298677 | L15: 0.290739 | M15: 0.289252 | N15: 0.280437 | O15: =AVERAGE(D15:N15) -> 0.2870073 | Q15: =(('Mode 0'!O3)/(O15)) -> 6.4569741 | R15: =_xlfn.PERCENTOF(Q15,C15)*100 -> 80.712176
A16: 2048 | B16: 1 | C16: 8 | D16: static | E16: 5.203454 | F16: 5.432075 | G16: 5.21282 | H16: 5.507528 | I16: 5.541547 | J16: 5.150893 | K16: 5.052306 | L16: 5.279991 | M16: 5.149139 | N16: 5.285355 | O16: =AVERAGE(D16:N16) -> 5.2815108 | Q16: =(('Mode 0'!O4)/(O16)) -> 9.0427255 | R16: =_xlfn.PERCENTOF(Q16,C16)*100 -> 113.03407
A18: 512 | B18: 1 | C18: 12 | D18: static | E18: 0.03348 | F18: 0.032647 | G18: 0.032262 | H18: 0.032766 | I18: 0.028229 | J18: 0.029918 | K18: 0.031395 | L18: 0.033005 | M18: 0.029891 | N18: 0.028545 | O18: =AVERAGE(D18:N18) -> 0.0312138 | Q18: =(('Mode 0'!O2)/(O18)) -> 7.3972954 | R18: =_xlfn.PERCENTOF(Q18,C18)*100 -> 61.644129
A19: 1024 | B19: 1 | C19: 12 | D19: static | E19: 0.300193 | F19: 0.311823 | G19: 0.30388 | H19: 0.29991 | I19: 0.303638 | J19: 0.313984 | K19: 0.302389 | L19: 0.305025 | M19: 0.311345 | N19: 0.307049 | O19: =AVERAGE(D19:N19) -> 0.3059236 | Q19: =(('Mode 0'!O3)/(O19)) -> 6.0577174 | R19: =_xlfn.PERCENTOF(Q19,C19)*100 -> 50.480978
A20: 2048 | B20: 1 | C20: 12 | D20: static | E20: 5.236927 | F20: 5.290203 | G20: 5.145202 | H20: 5.403665 | I20: 5.318367 | J20: 5.714818 | K20: 5.397779 | L20: 5.453695 | M20: 5.419946 | N20: 5.274553 | O20: =AVERAGE(D20:N20) -> 5.3655155 | Q20: =(('Mode 0'!O4)/(O20)) -> 8.9011489 | R20: =_xlfn.PERCENTOF(Q20,C20)*100 -> 74.176241
A22: 512 | B22: 1 | C22: 16 | D22: static | E22: 0.023022 | F22: 0.023664 | G22: 0.023007 | H22: 0.028768 | I22: 0.026266 | J22: 0.024626 | K22: 0.026476 | L22: 0.025804 | M22: 0.025364 | N22: 0.026576 | O22: =AVERAGE(D22:N22) -> 0.0253573 | Q22: =(('Mode 0'!O2)/(O22)) -> 9.1057684 | R22: =_xlfn.PERCENTOF(Q22,C22)*100 -> 56.911052
A23: 1024 | B23: 1 | C23: 16 | D23: static | E23: 0.258338 | F23: 0.251374 | G23: 0.253747 | H23: 0.254482 | I23: 0.258721 | J23: 0.256109 | K23: 0.253881 | L23: 0.273675 | M23: 0.256672 | N23: 0.2543 | O23: =AVERAGE(D23:N23) -> 0.2571299 | Q23: =(('Mode 0'!O3)/(O23)) -> 7.207247 | R23: =_xlfn.PERCENTOF(Q23,C23)*100 -> 45.045294
A24: 2048 | B24: 1 | C24: 16 | D24: static | E24: 4.273195 | F24: 4.165786 | G24: 3.98143 | H24: 4.277022 | I24: 4.25476 | J24: 4.203446 | K24: 4.295322 | L24: 4.381657 | M24: 4.280094 | N24: 4.301609 | O24: =AVERAGE(D24:N24) -> 4.2414321 | Q24: =(('Mode 0'!O4)/(O24)) -> 11.260171 | R24: =_xlfn.PERCENTOF(Q24,C24)*100 -> 70.376071
A26: 512 | B26: 1 | C26: 20 | D26: static | E26: 0.002048 | F26: 0.017888 | G26: 0.020311 | H26: 0.022315 | I26: 0.023002 | J26: 0.021467 | K26: 0.029285 | L26: 0.020863 | M26: 0.02065 | N26: 0.020009 | O26: =AVERAGE(D26:N26) -> 0.0197838 | Q26: =(('Mode 0'!O2)/(O26)) -> 11.671049 | R26: =_xlfn.PERCENTOF(Q26,C26)*100 -> 58.355245
A27: 1024 | B27: 1 | C27: 20 | D27: static | E27: 0.228668 | F27: 0.229288 | G27: 0.239325 | H27: 0.23597 | I27: 0.229916 | J27: 0.237441 | K27: 0.236072 | L27: 0.246045 | M27: 0.228797 | N27: 0.242636 | O27: =AVERAGE(D27:N27) -> 0.2354158 | Q27: =(('Mode 0'!O3)/(O27)) -> 7.8720235 | R27: =_xlfn.PERCENTOF(Q27,C27)*100 -> 39.360117
A28: 2048 | B28: 1 | C28: 20 | D28: static | E28: 4.210644 | F28: 4.278598 | G28: 4.12004 | H28: 3.901226 | I28: 3.796678 | J28: 3.787333 | K28: 4.076492 | L28: 3.74874 | M28: 3.809631 | N28: 4.05108 | O28: =AVERAGE(D28:N28) -> 3.9780462 | Q28: =(('Mode 0'!O4)/(O28)) -> 12.005706 | R28: =_xlfn.PERCENTOF(Q28,C28)*100 -> 60.028529
A30: N | B30: Mode | C30: Threads | D30: Schedule | E30: Time 1 | F30: Time 2 | G30: Time 3 | H30: Time 4 | I30: Time 5 | J30: Time 6 | K30: Time 7 | L30: Time 8 | M30: Time 9 | N30: Time 10 | O30: AverageTime | Q30: Speedup | R30: Efficiency
A31: 512 | B31: 1 | C31: 1 | D31: dynamic | E31: 0.230252 | F31: 0.223652 | G31: 0.231009 | H31: 0.228513 | I31: 0.225635 | J31: 0.229792 | K31: 0.236884 | L31: 0.227837 | M31: 0.233019 | N31: 0.232147 | O31: =AVERAGE(D31:N31) -> 0.229874 | Q31: =(('Mode 0'!O2)/(O31)) -> 1.0044533 | R31: =_xlfn.PERCENTOF(Q31,C31)*100 -> 100.44533
A32: 1024 | B32: 1 | C32: 1 | D32: dynamic | E32: 1.861565 | F32: 1.864356 | G32: 1.857 | H32: 1.854197 | I32: 1.862503 | J32: 1.873014 | K32: 1.862701 | L32: 1.857252 | M32: 1.865233 | N32: 1.859771 | O32: =AVERAGE(D32:N32) -> 1.8617592 | Q32: =(('Mode 0'!O3)/(O32)) -> 0.99540193 | R32: =_xlfn.PERCENTOF(Q32,C32)*100 -> 99.540193
A33: 2048 | B33: 1 | C33: 1 | D33: dynamic | E33: 49.534456 | F33: 45.252215 | G33: 48.039264 | H33: 50.251034 | I33: 48.605631 | J33: 49.301245 | K33: 48.980024 | L33: 47.440326 | M33: 47.358163 | N33: 49.658012 | O33: =AVERAGE(D33:N33) -> 48.442037 | Q33: =(('Mode 0'!O4)/(O33)) -> 0.98590512 | R33: =_xlfn.PERCENTOF(Q33,C33)*100 -> 98.590512
A35: 512 | B35: 1 | C35: 2 | D35: dynamic | E35: 0.121625 | F35: 0.117976 | G35: 0.11806 | H35: 0.122214 | I35: 0.122262 | J35: 0.124084 | K35: 0.120401 | L35: 0.120994 | M35: 0.122195 | N35: 0.124521 | O35: =AVERAGE(D35:N35) -> 0.1214332 | Q35: =(('Mode 0'!O2)/(O35)) -> 1.901438 | R35: =_xlfn.PERCENTOF(Q35,C35)*100 -> 95.0719
A36: 1024 | B36: 1 | C36: 2 | D36: dynamic | E36: 1.008623 | F36: 0.995914 | G36: 0.1017927 | H36: 1.005925 | I36: 1.010706 | J36: 1.00418 | K36: 0.998304 | L36: 0.102767 | M36: 1.00253 | N36: 1.010361 | O36: =AVERAGE(D36:N36) -> 0.82411027 | Q36: =(('Mode 0'!O3)/(O36)) -> 2.2487266 | R36: =_xlfn.PERCENTOF(Q36,C36)*100 -> 112.43633
A37: 2048 | B37: 1 | C37: 2 | D37: dynamic | E37: 32.231718 | F37: 30.654693 | G37: 29.436701 | H37: 33.020048 | I37: 27.563886 | J37: 28.968951 | K37: 28.486201 | L37: 29.300145 | M37: 30.341572 | N37: 31.0294 | O37: =AVERAGE(D37:N37) -> 30.103332 | Q37: =(('Mode 0'!O4)/(O37)) -> 1.5865105 | R37: =_xlfn.PERCENTOF(Q37,C37)*100 -> 79.325526
A39: 512 | B39: 1 | C39: 4 | D39: dynamic | E39: 0.069797 | F39: 0.064435 | G39: 0.067688 | H39: 0.066493 | I39: 0.067568 | J39: 0.068371 | K39: 0.062184 | L39: 0.064184 | M39: 0.06467 | N39: 0.066466 | O39: =AVERAGE(D39:N39) -> 0.0661856 | Q39: =(('Mode 0'!O2)/(O39)) -> 3.4886395 | R39: =_xlfn.PERCENTOF(Q39,C39)*100 -> 87.215988
A40: 1024 | B40: 1 | C40: 4 | D40: dynamic | E40: 0.533133 | F40: 0.516811 | G40: 0.527071 | H40: 0.531779 | I40: 0.506629 | J40: 0.532989 | K40: 0.52192 | L40: 0.531428 | M40: 0.507826 | N40: 0.532202 | O40: =AVERAGE(D40:N40) -> 0.5241788 | Q40: =(('Mode 0'!O3)/(O40)) -> 3.5354324 | R40: =_xlfn.PERCENTOF(Q40,C40)*100 -> 88.385809
A41: 2048 | B41: 1 | C41: 4 | D41: dynamic | E41: 10.65765 | F41: 10.713829 | G41: 11.242481 | H41: 10.894768 | I41: 11.048832 | J41: 11.084902 | K41: 10.844449 | L41: 10.863698 | M41: 10.667119 | N41: 10.527676 | O41: =AVERAGE(D41:N41) -> 10.85454 | Q41: =(('Mode 0'!O4)/(O41)) -> 4.3999332 | R41: =_xlfn.PERCENTOF(Q41,C41)*100 -> 109.99833
A43: 512 | B43: 1 | C43: 8 | D43: dynamic | E43: 0.037044 | F43: 0.037228 | G43: 0.035102 | H43: 0.037005 | I43: 0.03697 | J43: 0.03662 | K43: 0.037147 | L43: 0.038905 | M43: 0.036695 | N43: 0.036395 | O43: =AVERAGE(D43:N43) -> 0.0369111 | Q43: =(('Mode 0'!O2)/(O43)) -> 6.2555085 | R43: =_xlfn.PERCENTOF(Q43,C43)*100 -> 78.193856
A44: 1024 | B44: 1 | C44: 8 | D44: dynamic | E44: 0.280002 | F44: 0.267725 | G44: 0.281408 | H44: 0.279327 | I44: 0.278242 | J44: 0.288311 | K44: 0.270211 | L44: 0.279845 | M44: 0.272666 | N44: 0.278748 | O44: =AVERAGE(D44:N44) -> 0.2776485 | Q44: =(('Mode 0'!O3)/(O44)) -> 6.6746217 | R44: =_xlfn.PERCENTOF(Q44,C44)*100 -> 83.432771
A45: 2048 | B45: 1 | C45: 8 | D45: dynamic | E45: 5.059407 | F45: 5.3375666 | G45: 6.189463 | H45: 5.73298 | I45: 5.578665 | J45: 5.402016 | K45: 5.171803 | L45: 5.256482 | M45: 5.17322 | N45: 5.14636 | O45: =AVERAGE(D45:N45) -> 5.4047963 | Q45: =(('Mode 0'!O4)/(O45)) -> 8.8364575 | R45: =_xlfn.PERCENTOF(Q45,C45)*100 -> 110.45572
A47: 512 | B47: 1 | C47: 12 | D47: dynamic | E47: 0.028379 | F47: 0.027782 | G47: 0.027074 | H47: 0.030268 | I47: 0.027045 | J47: 0.028005 | K47: 0.027075 | L47: 0.026991 | M47: 0.027277 | N47: 0.027742 | O47: =AVERAGE(D47:N47) -> 0.0277638 | Q47: =(('Mode 0'!O2)/(O47)) -> 8.3165021 | R47: =_xlfn.PERCENTOF(Q47,C47)*100 -> 69.304184
A48: 1024 | B48: 1 | C48: 12 | D48: dynamic | E48: 0.246457 | F48: 0.252304 | G48: 0.240421 | H48: 0.239026 | I48: 0.250434 | J48: 0.25142 | K48: 0.240491 | L48: 0.242078 | M48: 0.247747 | N48: 0.247216 | O48: =AVERAGE(D48:N48) -> 0.2457594 | Q48: =(('Mode 0'!O3)/(O48)) -> 7.5407032 | R48: =_xlfn.PERCENTOF(Q48,C48)*100 -> 62.839194
A49: 2048 | B49: 1 | C49: 12 | D49: dynamic | E49: 4.624055 | F49: 4.839227 | G49: 4.529415 | H49: 4.589847 | I49: 4.771634 | J49: 4.99106 | K49: 4.513997 | L49: 4.58594 | M49: 4.618054 | N49: 4.58897 | O49: =AVERAGE(D49:N49) -> 4.6652199 | Q49: =(('Mode 0'!O4)/(O49)) -> 10.237299 | R49: =_xlfn.PERCENTOF(Q49,C49)*100 -> 85.310827
A51: 512 | B51: 1 | C51: 16 | D51: dynamic | E51: 0.022551 | F51: 0.022281 | G51: 0.022654 | H51: 0.021239 | I51: 0.021635 | J51: 0.020955 | K51: 0.020849 | L51: 0.021931 | M51: 0.021607 | N51: 0.023281 | O51: =AVERAGE(D51:N51) -> 0.0218983 | Q51: =(('Mode 0'!O2)/(O51)) -> 10.544092 | R51: =_xlfn.PERCENTOF(Q51,C51)*100 -> 65.900578
A52: 1024 | B52: 1 | C52: 16 | D52: dynamic | E52: 0.207541 | F52: 0.1941 | G52: 0.189079 | H52: 0.194789 | I52: 0.19658 | J52: 0.197232 | K52: 0.186215 | L52: 0.205698 | M52: 0.181523 | N52: 0.192738 | O52: =AVERAGE(D52:N52) -> 0.1945495 | Q52: =(('Mode 0'!O3)/(O52)) -> 9.5255896 | R52: =_xlfn.PERCENTOF(Q52,C52)*100 -> 59.534935
...

Sheet Mode 2
A1: N | B1: Mode | C1: Threads | D1: Schedule | E1: Time 1 | F1: Time 2 | G1: Time 3 | H1: Time 4 | I1: Time 5 | J1: Time 6 | K1: Time 7 | L1: Time 8 | M1: Time 9 | N1: Time 10 | O1: AverageTime | Q1: Speedup | R1: Efficiency (%)
A2: 512 | B2: 2 | C2: 1 | E2: 0.228163 | F2: 0.21996 | G2: 0.225937 | H2: 0.233784 | I2: 0.229217 | J2: 0.227251 | K2: 0.230125 | L2: 0.227072 | M2: 0.229992 | N2: 0.227795 | O2: =AVERAGE(D2:N2) -> 0.2279296 | Q2: =(('Mode 0'!O2)/(O2)) -> 1.013022 | R2: =Q2/C2*100 -> 101.3022
A3: 1024 | B3: 2 | C3: 1 | E3: 1.870144 | F3: 1.853698 | G3: 1.856928 | H3: 1.875441 | I3: 1.874735 | J3: 1.862972 | K3: 1.86439 | L3: 1.873895 | M3: 1.857963 | N3: 1.866163 | O3: =AVERAGE(D3:N3) -> 1.8656329 | Q3: =(('Mode 0'!O3)/(O3)) -> 0.99333513 | R3: =Q3/C3*100 -> 99.333513
A4: 2048 | B4: 2 | C4: 1 | E4: 45.508709 | F4: 49.957098 | G4: 50.442109 | H4: 52.096716 | I4: 47.252016 | J4: 47.875164 | K4: 47.879256 | L4: 48.170202 | M4: 46.945018 | N4: 50.965458 | O4: =AVERAGE(D4:N4) -> 48.709175 | Q4: =(('Mode 0'!O4)/(O4)) -> 0.98049808 | R4: =Q4/C4*100 -> 98.049808
A6: 512 | B6: 2 | C6: 2 | E6: 0.126847 | F6: 0.120842 | G6: 0.119041 | H6: 0.118317 | I6: 0.123407 | J6: 0.121952 | K6: 0.117616 | L6: 0.119845 | M6: 0.119265 | N6: 0.11734 | O6: =AVERAGE(D6:N6) -> 0.1204472 | Q6: =(('Mode 0'!O2)/(O6)) -> 1.9170035 | R6: =Q6/C6*100 -> 95.850173
A7: 1024 | B7: 2 | C7: 2 | E7: 1.008986 | F7: 1.0151 | G7: 1.006706 | H7: 0.996542 | I7: 1.013782 | J7: 0.971403 | K7: 0.99307 | L7: 1.013116 | M7: 1.02675 | N7: 1.006646 | O7: =AVERAGE(D7:N7) -> 1.0052101 | Q7: =(('Mode 0'!O3)/(O7)) -> 1.8435934 | R7: =Q7/C7*100 -> 92.17967
A8: 2048 | B8: 2 | C8: 2 | E8: 27.00806 | F8: 28.892086 | G8: 28.999748 | H8: 29.577101 | I8: 27.544127 | J8: 26.809077 | K8: 27.667162 | L8: 28.204803 | M8: 28.780884 | N8: 27.980506 | O8: =AVERAGE(D8:N8) -> 28.146355 | Q8: =(('Mode 0'!O4)/(O8)) -> 1.6968183 | R8: =Q8/C8*100 -> 84.840917
A10: 512 | B10: 2 | C10: 4 | E10: 0.068656 | F10: 0.066456 | G10: 0.063798 | H10: 0.066609 | I10: 0.067515 | J10: 0.06811 | K10: 0.067411 | L10: 0.065294 | M10: 0.063455 | N10: 0.068629 | O10: =AVERAGE(D10:N10) -> 0.0665933 | Q10: =(('Mode 0'!O2)/(O10)) -> 3.4672812 | R10: =Q10/C10*100 -> 86.682031
A11: 1024 | B11: 2 | C11: 4 | E11: 0.535076 | F11: 0.527571 | G11: 0.512367 | H11: 0.531516 | I11: 0.506363 | J11: 0.522514 | K11: 0.526355 | L11: 0.526149 | M11: 0.516318 | N11: 0.50948 | O11: =AVERAGE(D11:N11) -> 0.5213709 | Q11: =(('Mode 0'!O3)/(O11)) -> 3.5544728 | R11: =Q11/C11*100 -> 88.861821
A12: 2048 | B12: 2 | C12: 4 | E12: 12.44064 | F12: 11.409314 | G12: 10.962714 | H12: 10.916687 | I12: 11.169786 | J12: 10.724378 | K12: 11.397408 | L12: 11.071325 | M12: 10.649613 | N12: 10.819449 | O12: =AVERAGE(D12:N12) -> 11.156131 | Q12: =(('Mode 0'!O4)/(O12)) -> 4.2809869 | R12: =Q12/C12*100 -> 107.02467
A14: 512 | B14: 2 | C14: 8 | E14: 0.035363 | F14: 0.03916 | G14: 0.045186 | H14: 0.03961 | I14: 0.035465 | J14: 0.036524 | K14: 0.050694 | L14: 0.034436 | M14: 0.046288 | N14: 0.047779 | O14: =AVERAGE(D14:N14) -> 0.0410505 | Q14: =(('Mode 0'!O2)/(O14)) -> 5.6247232 | R14: =Q14/C14*100 -> 70.30904
A15: 1024 | B15: 2 | C15: 8 | E15: 0.278274 | F15: 0.305874 | G15: 0.279244 | H15: 0.308296 | I15: 0.287697 | J15: 0.284229 | K15: 0.28287 | L15: 0.279318 | M15: 0.282978 | N15: 0.289775 | O15: =AVERAGE(D15:N15) -> 0.2878555 | Q15: =(('Mode 0'!O3)/(O15)) -> 6.4379479 | R15: =Q15/C15*100 -> 80.474348
A16: 2048 | B16: 2 | C16: 8 | E16: 5.264455 | F16: 5.508765 | G16: 5.844512 | H16: 5.300101 | I16: 5.376828 | J16: 5.261251 | K16: 5.936492 | L16: 5.100895 | M16: 5.489656 | N16: 5.498659 | O16: =AVERAGE(D16:N16) -> 5.4581614 | Q16: =(('Mode 0'!O4)/(O16)) -> 8.7500623 | R16: =Q16/C16*100 -> 109.37578
A18: 512 | B18: 2 | C18: 12 | E18: 0.030454 | F18: 0.034435 | G18: 0.029853 | H18: 0.030477 | I18: 0.035483 | J18: 0.030916 | K18: 0.02729 | L18: 0.033964 | M18: 0.032278 | N18: 0.031266 | O18: =AVERAGE(D18:N18) -> 0.0316416 | Q18: =(('Mode 0'!O2)/(O18)) -> 7.2972827 | R18: =Q18/C18*100 -> 60.810689
A19: 1024 | B19: 2 | C19: 12 | E19: 0.30121 | F19: 0.310079 | G19: 0.300522 | H19: 0.305574 | I19: 0.297639 | J19: 0.308672 | K19: 0.303241 | L19: 0.306239 | M19: 0.31537 | N19: 0.312563 | O19: =AVERAGE(D19:N19) -> 0.3061109 | Q19: =(('Mode 0'!O3)/(O19)) -> 6.0540108 | R19: =Q19/C19*100 -> 50.45009
A20: 2048 | B20: 2 | C20: 12 | E20: 5.368636 | F20: 5.373017 | G20: 5.341513 | H20: 5.183616 | I20: 5.445674 | J20: 5.468871 | K20: 5.205559 | L20: 5.4371 | M20: 5.483086 | N20: 5.10209 | O20: =AVERAGE(D20:N20) -> 5.3409162 | Q20: =(('Mode 0'!O4)/(O20)) -> 8.942146 | R20: =Q20/C20*100 -> 74.517883
A22: 512 | B22: 2 | C22: 16 | E22: 0.020579 | F22: 0.020935 | G22: 0.021029 | H22: 0.026485 | I22: 0.021743 | J22: 0.02371 | K22: 0.021062 | L22: 0.023586 | M22: 0.026969 | N22: 0.023989 | O22: =AVERAGE(D22:N22) -> 0.0230087 | Q22: =(('Mode 0'!O2)/(O22)) -> 10.035234 | R22: =Q22/C22*100 -> 62.720216
A23: 1024 | B23: 2 | C23: 16 | E23: 0.243442 | F23: 0.259837 | G23: 0.253217 | H23: 0.251966 | I23: 0.25175 | J23: 0.26625 | K23: 0.260189 | L23: 0.267081 | M23: 0.252558 | N23: 0.265177 | O23: =AVERAGE(D23:N23) -> 0.2571467 | Q23: =(('Mode 0'!O3)/(O23)) -> 7.2067761 | R23: =Q23/C23*100 -> 45.042351
A24: 2048 | B24: 2 | C24: 16 | E24: 4.377189 | F24: 4.571785 | G24: 4.161082 | H24: 4.145853 | I24: 4.086328 | J24: 4.33889 | K24: 4.068783 | L24: 4.313989 | M24: 4.321116 | N24: 4.484133 | O24: =AVERAGE(D24:N24) -> 4.2869148 | Q24: =(('Mode 0'!O4)/(O24)) -> 11.140705 | R24: =Q24/C24*100 -> 69.629405
A26: 512 | B26: 2 | C26: 20 | E26: 0.018226 | F26: 0.019372 | G26: 0.017926 | H26: 0.027 | I26: 0.01956 | J26: 0.019625 | K26: 0.017644 | L26: 0.018976 | M26: 0.01921 | N26: 0.018485 | O26: =AVERAGE(D26:N26) -> 0.0196024 | Q26: =(('Mode 0'!O2)/(O26)) -> 11.779053 | R26: =Q26/C26*100 -> 58.895263
A27: 1024 | B27: 2 | C27: 20 | E27: 0.244329 | F27: 0.252946 | G27: 0.242682 | H27: 0.254427 | I27: 0.237631 | J27: 0.238876 | K27: 0.250598 | L27: 0.236555 | M27: 0.267051 | N27: 0.251729 | O27: =AVERAGE(D27:N27) -> 0.2476824 | Q27: =(('Mode 0'!O3)/(O27)) -> 7.4821574 | R27: =Q27/C27*100 -> 37.410787
A28: 2048 | B28: 2 | C28: 20 | E28: 3.964942 | F28: 3.900904 | G28: 4.268151 | H28: 4.120037 | I28: 4.061919 | J28: 3.885625 | K28: 3.850507 | L28: 4.192773 | M28: 4.051962 | N28: 4.292881 | O28: =AVERAGE(D28:N28) -> 4.0589701 | Q28: =(('Mode 0'!O4)/(O28)) -> 11.766347 | R28: =Q28/C28*100 -> 58.831737

Sheet Mode 3
A1: N | B1: Mode | C1: Threads | D1: Schedule | E1: Time 1 (atomic) | F1: Time 1 (critical) | G1: Time 2 (atomic) | H1: Time 2 (critical) | I1: Time 3 (atomic) | J1: Time 3 (critical) | K1: Time 4 (atomic) | L1: Time 4 (critical) | M1: Time 5 (atomic) | N1: Time 5 (critical) | O1: Average Atomic Time | P1: Average Critical Time | Q1: Total Average Time | S1: Speedup Atomic | T1: Speedup Critical | U1: Speedup Average | V1: Efficiency Atomic (%) | W1: Efficiency Critical (%) | X1: Efficiency Average (%)
A2: 512 | B2: 3 | C2: 1 | E2: 0.23573 | F2: 0.237436 | G2: 0.227597 | H2: 0.229316 | I2: 0.235378 | J2: 0.237085 | K2: 0.240901 | L2: 0.242615 | M2: 0.236937 | N2: 0.238646 | O2: =AVERAGE(E2,G2,I2,K2,M2) -> 0.2353086 | P2: =AVERAGE(F2,H2,J2,L2,N2) -> 0.2370196 | Q2: =AVERAGE(O2:P2) -> 0.2361641 | S2: =(('Mode 0'!O2)/(O2)) -> 0.98125483 | T2: =(('Mode 0'!$O$2)/(P2)) -> 0.97417133 | U2: =(('Mode 0'!$O$2)/(Q2)) -> 0.97770025 | V2: =_xlfn.PERCENTOF(S2,C2)*100 -> 98.125483 | W2: =_xlfn.PERCENTOF(T2,$C2)*100 -> 97.417133 | X2: =_xlfn.PERCENTOF(U2,$C2)*100 -> 97.770025
A3: 1024 | B3: 3 | C3: 1 | E3: 1.859313 | F3: 1.866269 | G3: 1.880049 | H3: 1.887082 | I3: 1.872542 | J3: 1.879475 | K3: 1.860433 | L3: 1.867438 | M3: 1.854648 | N3: 1.862597 | O3: =AVERAGE(E3,G3,I3,K3,M3) -> 1.865397 | P3: =AVERAGE(F3,H3,J3,L3,N3) -> 1.8725722 | Q3: =AVERAGE(O3:P3) -> 1.8689846 | S3: =(('Mode 0'!O3)/(O3)) -> 0.99346075 | T3: =(('Mode 0'!$O$3)/(P3)) -> 0.98965407 | U3: =(('Mode 0'!$O$3)/(Q3)) -> 0.99155376 | V3: =_xlfn.PERCENTOF(S3,C3)*100 -> 99.346075 | W3: =_xlfn.PERCENTOF(T3,$C3)*100 -> 98.965407 | X3: =_xlfn.PERCENTOF(U3,$C3)*100 -> 99.155376
A4: 2048 | B4: 3 | C4: 1 | E4: 49.855568 | F4: 49.884472 | G4: 50.79401 | H4: 50.823365 | I4: 47.426813 | J4: 47.455096 | K4: 46.300276 | L4: 46.300276 | M4: 46.557997 | N4: 46.586774 | O4: =AVERAGE(E4,G4,I4,K4,M4) -> 48.186933 | P4: =AVERAGE(F4,H4,J4,L4,N4) -> 48.209997 | Q4: =AVERAGE(O4:P4) -> 48.198465 | S4: =(('Mode 0'!O4)/(O4)) -> 0.99112455 | T4: =(('Mode 0'!$O$4)/(P4)) -> 0.9906504 | U4: =(('Mode 0'!$O$4)/(Q4)) -> 0.99088742 | V4: =_xlfn.PERCENTOF(S4,C4)*100 -> 99.112455 | W4: =_xlfn.PERCENTOF(T4,$C4)*100 -> 99.06504 | X4: =_xlfn.PERCENTOF(U4,$C4)*100 -> 99.088742
A6: 512 | B6: 3 | C6: 2 | E6: 0.124982 | F6: 0.126136 | G6: 0.122807 | H6: 0.125001 | I6: 0.124408 | J6: 0.127504 | K6: 0.121341 | L6: 0.124161 | M6: 0.126767 | N6: 0.129847 | O6: =AVERAGE(E6,G6,I6,K6,M6) -> 0.124061 | P6: =AVERAGE(F6,H6,J6,L6,N6) -> 0.1265298 | Q6: =AVERAGE(O6:P6) -> 0.1252954 | S6: =(('Mode 0'!O2)/(O6)) -> 1.8611627 | T6: =(('Mode 0'!$O$2)/(P6)) -> 1.8248484 | U6: =(('Mode 0'!$O$2)/(Q6)) -> 1.8428266 | V6: =_xlfn.PERCENTOF(S6,C6)*100 -> 93.058133 | W6: =_xlfn.PERCENTOF(T6,$C6)*100 -> 91.242419 | X6: =_xlfn.PERCENTOF(U6,$C6)*100 -> 92.141332
A7: 1024 | B7: 3 | C7: 2 | E7: 1.031102 | F7: 1.042224 | G7: 1.024351 | H7: 1.038645 | I7: 1.034596 | J7: 1.048474 | K7: 1.026643 | L7: 1.039045 | M7: 1.018083 | N7: 1.030685 | O7: =AVERAGE(E7,G7,I7,K7,M7) -> 1.026955 | P7: =AVERAGE(F7,H7,J7,L7,N7) -> 1.0398146 | Q7: =AVERAGE(O7:P7) -> 1.0333848 | S7: =(('Mode 0'!O3)/(O7)) -> 1.8045569 | T7: =(('Mode 0'!$O$3)/(P7)) -> 1.7822395 | U7: =(('Mode 0'!$O$3)/(Q7)) -> 1.7933288 | V7: =_xlfn.PERCENTOF(S7,C7)*100 -> 90.227843 | W7: =_xlfn.PERCENTOF(T7,$C7)*100 -> 89.111977 | X7: =_xlfn.PERCENTOF(U7,$C7)*100 -> 89.666439
A8: 2048 | B8: 3 | C8: 2 | E8: 27.378058 | F8: 27.492432 | G8: 29.821561 | H8: 29.869888 | I8: 29.237987 | J8: 29.275955 | K8: 27.881506 | L8: 27.931821 | M8: 27.012744 | N8: 27.091428 | O8: =AVERAGE(E8,G8,I8,K8,M8) -> 28.266371 | P8: =AVERAGE(F8,H8,J8,L8,N8) -> 28.332305 | Q8: =AVERAGE(O8:P8) -> 28.299338 | S8: =(('Mode 0'!O4)/(O8)) -> 1.6896138 | T8: =(('Mode 0'!$O$4)/(P8)) -> 1.6856819 | U8: =(('Mode 0'!$O$4)/(Q8)) -> 1.6876456 | V8: =_xlfn.PERCENTOF(S8,C8)*100 -> 84.480692 | W8: =_xlfn.PERCENTOF(T8,$C8)*100 -> 84.284093 | X8: =_xlfn.PERCENTOF(U8,$C8)*100 -> 84.382278
A10: 512 | B10: 3 | C10: 4 | E10: 0.069939 | F10: 0.083516 | G10: 0.071175 | H10: 0.084636 | I10: 0.068806 | J10: 0.077854 | K10: 0.071286 | L10: 0.078831 | M10: 0.074229 | N10: 0.082858 | O10: =AVERAGE(E10,G10,I10,K10,M10) -> 0.071087 | P10: =AVERAGE(F10,H10,J10,L10,N10) -> 0.081539 | Q10: =AVERAGE(O10:P10) -> 0.076313 | S10: =(('Mode 0'!O2)/(O10)) -> 3.2481002 | T10: =(('Mode 0'!$O$2)/(P10)) -> 2.8317455 | U10: =(('Mode 0'!$O$2)/(Q10)) -> 3.0256667 | V10: =_xlfn.PERCENTOF(S10,C10)*100 -> 81.202505 | W10: =_xlfn.PERCENTOF(T10,$C10)*100 -> 70.793639 | X10: =_xlfn.PERCENTOF(U10,$C10)*100 -> 75.641667
A11: 1024 | B11: 3 | C11: 4 | E11: 0.544444 | F11: 0.603806 | G11: 0.542459 | H11: 0.567438 | I11: 0.533958 | J11: 0.58903 | K11: 0.51962 | L11: 0.582244 | M11: 0.532835 | N11: 0.592968 | O11: =AVERAGE(E11,G11,I11,K11,M11) -> 0.5346632 | P11: =AVERAGE(F11,H11,J11,L11,N11) -> 0.5870972 | Q11: =AVERAGE(O11:P11) -> 0.5608802 | S11: =(('Mode 0'!O3)/(O11)) -> 3.4661048 | T11: =(('Mode 0'!$O$3)/(P11)) -> 3.1565449 | U11: =(('Mode 0'!$O$3)/(Q11)) -> 3.3040901 | V11: =_xlfn.PERCENTOF(S11,C11)*100 -> 86.652621 | W11: =_xlfn.PERCENTOF(T11,$C11)*100 -> 78.913624 | X11: =_xlfn.PERCENTOF(U11,$C11)*100 -> 82.602252
A12: 2048 | B12: 3 | C12: 4 | E12: 11.041368 | F12: 11.253543 | G12: 10.541799 | H12: 10.716241 | I12: 11.254731 | J12: 11.332972 | K12: 11.273565 | L12: 11.557062 | M12: 11.072057 | N12: 11.279775 | O12: =AVERAGE(E12,G12,I12,K12,M12) -> 11.036704 | P12: =AVERAGE(F12,H12,J12,L12,N12) -> 11.227919 | Q12: =AVERAGE(O12:P12) -> 11.132311 | S12: =(('Mode 0'!O4)/(O12)) -> 4.3273111 | T12: =(('Mode 0'!$O$4)/(P12)) -> 4.2536158 | U12: =(('Mode 0'!$O$4)/(Q12)) -> 4.290147 | V12: =_xlfn.PERCENTOF(S12,C12)*100 -> 108.18278 | W12: =_xlfn.PERCENTOF(T12,$C12)*100 -> 106.3404 | X12: =_xlfn.PERCENTOF(U12,$C12)*100 -> 107.25368
A14: 512 | B14: 3 | C14: 8 | E14: 0.038952 | F14: 0.057199 | G14: 0.040929 | H14: 0.053815 | I14: 0.043113 | J14: 0.061846 | K14: 0.043849 | L14: 0.060151 | M14: 0.041351 | N14: 0.061325 | O14: =AVERAGE(E14,G14,I14,K14,M14) -> 0.0416388 | P14: =AVERAGE(F14,H14,J14,L14,N14) -> 0.0588672 | Q14: =AVERAGE(O14:P14) -> 0.050253 | S14: =(('Mode 0'!O2)/(O14)) -> 5.5452535 | T14: =(('Mode 0'!$O$2)/(P14)) -> 3.9223489 | U14: =(('Mode 0'!$O$2)/(Q14)) -> 4.5947048 | V14: =_xlfn.PERCENTOF(S14,C14)*100 -> 69.315668 | W14: =_xlfn.PERCENTOF(T14,$C14)*100 -> 49.029362 | X14: =_xlfn.PERCENTOF(U14,$C14)*100 -> 57.43381
A15: 1024 | B15: 3 | C15: 8 | E15: 0.299062 | F15: 0.382594 | G15: 0.316747 | H15: 0.373768 | I15: 0.380469 | J15: 0.435285 | K15: 0.309258 | L15: 0.394753 | M15: 0.322785 | N15: 0.418704 | O15: =AVERAGE(E15,G15,I15,K15,M15) -> 0.3256642 | P15: =AVERAGE(F15,H15,J15,L15,N15) -> 0.4010208 | Q15: =AVERAGE(O15:P15) -> 0.3633425 | S15: =(('Mode 0'!O3)/(O15)) -> 5.6905202 | T15: =(('Mode 0'!$O$3)/(P15)) -> 4.6212034 | U15: =(('Mode 0'!$O$3)/(Q15)) -> 5.1004182 | V15: =_xlfn.PERCENTOF(S15,C15)*100 -> 71.131502 | W15: =_xlfn.PERCENTOF(T15,$C15)*100 -> 57.765043 | X15: =_xlfn.PERCENTOF(U15,$C15)*100 -> 63.755228
A16: 2048 | B16: 3 | C16: 8 | E16: 5.105399 | F16: 5.433331 | G16: 5.109958 | H16: 5.527658 | I16: 5.302663 | J16: 5.628623 | K16: 5.47105 | L16: 5.771865 | M16: 5.373938 | N16: 5.596785 | O16: =AVERAGE(E16,G16,I16,K16,M16) -> 5.2726016 | P16: =AVERAGE(F16,H16,J16,L16,N16) -> 5.5916524 | Q16: =AVERAGE(O16:P16) -> 5.432127 | S16: =(('Mode 0'!O4)/(O16)) -> 9.0580051 | T16: =(('Mode 0'!$O$4)/(P16)) -> 8.5411697 | U16: =(('Mode 0'!$O$4)/(Q16)) -> 8.7919985 | V16: =_xlfn.PERCENTOF(S16,C16)*100 -> 113.22506 | W16: =_xlfn.PERCENTOF(T16,$C16)*100 -> 106.76462 | X16: =_xlfn.PERCENTOF(U16,$C16)*100 -> 109.89998
A18: 512 | B18: 3 | C18: 12 | E18: 0.039197 | F18: 0.062584 | G18: 0.03486 | H18: 0.058936 | I18: 0.035769 | J18: 0.060976 | K18: 0.036524 | L18: 0.0644 | M18: 0.036228 | N18: 0.061904 | O18: =AVERAGE(E18,G18,I18,K18,M18) -> 0.0365156 | P18: =AVERAGE(F18,H18,J18,L18,N18) -> 0.06176 | Q18: =AVERAGE(O18:P18) -> 0.0491378 | S18: =(('Mode 0'!O2)/(O18)) -> 6.3232618 | T18: =(('Mode 0'!$O$2)/(P18)) -> 3.7386286 | U18: =(('Mode 0'!$O$2)/(Q18)) -> 4.6989833 | V18: =_xlfn.PERCENTOF(S18,C18)*100 -> 52.693849 | W18: =_xlfn.PERCENTOF(T18,$C18)*100 -> 31.155238 | X18: =_xlfn.PERCENTOF(U18,$C18)*100 -> 39.158194
A19: 1024 | B19: 3 | C19: 12 | E19: 0.32827 | F19: 0.419983 | G19: 0.319044 | H19: 0.408163 | I19: 0.33076 | J19: 0.427948 | K19: 0.343787 | L19: 0.414373 | M19: 0.314661 | N19: 0.419572 | O19: =AVERAGE(E19,G19,I19,K19,M19) -> 0.3273044 | P19: =AVERAGE(F19,H19,J19,L19,N19) -> 0.4180078 | Q19: =AVERAGE(O19:P19) -> 0.3726561 | S19: =(('Mode 0'!O3)/(O19)) -> 5.6620036 | T19: =(('Mode 0'!$O$3)/(P19)) -> 4.433407 | U19: =(('Mode 0'!$O$3)/(Q19)) -> 4.9729461 | V19: =_xlfn.PERCENTOF(S19,C19)*100 -> 47.183364 | W19: =_xlfn.PERCENTOF(T19,$C19)*100 -> 36.945058 | X19: =_xlfn.PERCENTOF(U19,$C19)*100 -> 41.441218
A20: 2048 | B20: 3 | C20: 12 | E20: 5.716463 | F20: 6.140805 | G20: 5.198459 | H20: 5.198459 | I20: 5.644948 | J20: 5.823071 | K20: 5.507579 | L20: 5.884237 | M20: 5.654261 | N20: 6.095537 | O20: =AVERAGE(E20,G20,I20,K20,M20) -> 5.544342 | P20: =AVERAGE(F20,H20,J20,L20,N20) -> 5.8284218 | Q20: =AVERAGE(O20:P20) -> 5.6863819 | S20: =(('Mode 0'!O4)/(O20)) -> 8.6140523 | T20: =(('Mode 0'!$O$4)/(P20)) -> 8.1941997 | U20: =(('Mode 0'!$O$4)/(Q20)) -> 8.3988823 | V20: =_xlfn.PERCENTOF(S20,C20)*100 -> 71.78377 | W20: =_xlfn.PERCENTOF(T20,$C20)*100 -> 68.284998 | X20: =_xlfn.PERCENTOF(U20,$C20)*100 -> 69.990686
A22: 512 | B22: 3 | C22: 16 | E22: 0.026006 | F22: 0.057267 | G22: 0.034743 | H22: 0.057942 | I22: 0.028917 | J22: 0.056925 | K22: 0.029926 | L22: 0.057718 | M22: 0.026361 | N22: 0.054044 | O22: =AVERAGE(E22,G22,I22,K22,M22) -> 0.0291906 | P22: =AVERAGE(F22,H22,J22,L22,N22) -> 0.0567792 | Q22: =AVERAGE(O22:P22) -> 0.0429849 | S22: =(('Mode 0'!O2)/(O22)) -> 7.9100018 | T22: =(('Mode 0'!$O$2)/(P22)) -> 4.0665895 | U22: =(('Mode 0'!$O$2)/(Q22)) -> 5.3716003 | V22: =_xlfn.PERCENTOF(S22,C22)*100 -> 49.437512 | W22: =_xlfn.PERCENTOF(T22,$C22)*100 -> 25.416185 | X22: =_xlfn.PERCENTOF(U22,$C22)*100 -> 33.572502
A23: 1024 | B23: 3 | C23: 16 | E23: 0.251814 | F23: 0.359717 | G23: 0.271516 | H23: 0.382817 | I23: 0.281021 | J23: 0.354279 | K23: 0.270739 | L23: 0.361615 | M23: 0.270403 | N23: 0.386134 | O23: =AVERAGE(E23,G23,I23,K23,M23) -> 0.2690986 | P23: =AVERAGE(F23,H23,J23,L23,N23) -> 0.3689124 | Q23: =AVERAGE(O23:P23) -> 0.3190055 | S23: =(('Mode 0'!O3)/(O23)) -> 6.8866902 | T23: =(('Mode 0'!$O$3)/(P23)) -> 5.0234112 | U23: =(('Mode 0'!$O$3)/(Q23)) -> 5.8093002 | V23: =_xlfn.PERCENTOF(S23,C23)*100 -> 43.041814 | W23: =_xlfn.PERCENTOF(T23,$C23)*100 -> 31.39632 | X23: =_xlfn.PERCENTOF(U23,$C23)*100 -> 36.308126
A24: 2048 | B24: 3 | C24: 16 | E24: 4.308652 | F24: 4.721122 | G24: 4.701239 | H24: 5.160684 | I24: 4.137105 | J24: 4.52295 | K24: 4.066554 | L24: 4.458375 | M24: 4.394184 | N24: 4.710359 | O24: =AVERAGE(E24,G24,I24,K24,M24) -> 4.3215468 | P24: =AVERAGE(F24,H24,J24,L24,N24) -> 4.714698 | Q24: =AVERAGE(O24:P24) -> 4.5181224 | S24: =(('Mode 0'!O4)/(O24)) -> 11.051425 | T24: =(('Mode 0'!$O$4)/(P24)) -> 10.129865 | U24: =(('Mode 0'!$O$4)/(Q24)) -> 10.570597 | V24: =_xlfn.PERCENTOF(S24,C24)*100 -> 69.071409 | W24: =_xlfn.PERCENTOF(T24,$C24)*100 -> 63.311654 | X24: =_xlfn.PERCENTOF(U24,$C24)*100 -> 66.066233
A26: 512 | B26: 3 | C26: 20 | E26: 0.0027019 | F26: 0.039668 | G26: 0.04926 | H26: 0.060071 | I26: 0.025122 | J26: 0.056611 | K26: 0.024867 | L26: 0.058524 | M26: 0.023533 | N26: 0.053766 | O26: =AVERAGE(E26,G26,I26,K26,M26) -> 0.02509678 | P26: =AVERAGE(F26,H26,J26,L26,N26) -> 0.053728 | Q26: =AVERAGE(O26:P26) -> 0.03941239 | S26: =(('Mode 0'!O2)/(O26)) -> 9.2002918 | T26: =(('Mode 0'!$O$2)/(P26)) -> 4.2975302 | U26: =(('Mode 0'!$O$2)/(Q26)) -> 5.8585054 | V26: =_xlfn.PERCENTOF(S26,C26)*100 -> 46.001459 | W26: =_xlfn.PERCENTOF(T26,$C26)*100 -> 21.487651 | X26: =_xlfn.PERCENTOF(U26,$C26)*100 -> 29.292527
A27: 1024 | B27: 3 | C27: 20 | E27: 0.240524 | F27: 0.338334 | G27: 0.235253 | H27: 0.347818 | I27: 0.24011 | J27: 0.359175 | K27: 0.237248 | L27: 0.338035 | M27: 0.241644 | N27: 0.338259 | O27: =AVERAGE(E27,G27,I27,K27,M27) -> 0.2389558 | P27: =AVERAGE(F27,H27,J27,L27,N27) -> 0.3443242 | Q27: =AVERAGE(O27:P27) -> 0.29164 | S27: =(('Mode 0'!O3)/(O27)) -> 7.7554037 | T27: =(('Mode 0'!$O$3)/(P27)) -> 5.3821332 | U27: =(('Mode 0'!$O$3)/(Q27)) -> 6.3544051 | V27: =_xlfn.PERCENTOF(S27,C27)*100 -> 38.777019 | W27: =_xlfn.PERCENTOF(T27,$C27)*100 -> 26.910666 | X27: =_xlfn.PERCENTOF(U27,$C27)*100 -> 31.772025
A28: 2048 | B28: 3 | C28: 20 | E28: 4.445529 | F28: 4.857507 | G28: 4.157122 | H28: 4.568557 | I28: 4.190751 | J28: 4.663989 | K28: 4.020398 | L28: 4.425327 | M28: 4.99404 | N28: 5.353482 | O28: =AVERAGE(E28,G28,I28,K28,M28) -> 4.361568 | P28: =AVERAGE(F28,H28,J28,L28,N28) -> 4.7737724 | Q28: =AVERAGE(O28:P28) -> 4.5676702 | S28: =(('Mode 0'!O4)/(O28)) -> 10.950019 | T28: =(('Mode 0'!$O$4)/(P28)) -> 10.00451 | U28: =(('Mode 0'!$O$4)/(Q28)) -> 10.455933 | V28: =_xlfn.PERCENTOF(S28,C28)*100 -> 54.750095 | W28: =_xlfn.PERCENTOF(T28,$C28)*100 -> 50.022548 | X28: =_xlfn.PERCENTOF(U28,$C28)*100 -> 52.279663

Sheet Mode 4
A1: N | B1: Mode | C1: Threads | D1: Schedule | E1: Time 1 | F1: Time 2 | G1: Time 3 | H1: Time 4 | I1: Time 5 | J1: Time 6 | K1: Time 7 | L1: Time 8 | M1: Time 9 | N1: Time 10 | O1: AverageTime | Q1: Speedup | R1: Efficiency (%)
A2: 512 | B2: 4 | C2: 1 | E2: 0.234406 | F2: 0.227862 | G2: 0.277202 | H2: 0.239575 | I2: 0.239575 | J2: 0.233907 | K2: 0.2277 | L2: 0.240129 | M2: 0.223857 | N2: 0.22707 | O2: =AVERAGE(D2:N2) -> 0.2371283 | Q2: =(('Mode 0'!O2)/(O2)) -> 0.97372477 | R2: =_xlfn.PERCENTOF(Q2,C2)*100 -> 97.372477
A3: 1024 | B3: 4 | C3: 1 | E3: 1.853999 | F3: 1.883649 | G3: 1.858597 | H3: 1.870235 | I3: 1.851914 | J3: 1.880604 | K3: 1.885344 | L3: 1.865445 | M3: 1.872367 | N3: 1.855793 | O3: =AVERAGE(D3:N3) -> 1.8677947 | Q3: =(('Mode 0'!O3)/(O3)) -> 0.99218544 | R3: =_xlfn.PERCENTOF(Q3,C3)*100 -> 99.218544
A4: 2048 | B4: 4 | C4: 1 | E4: 46.384264 | F4: 47.747829 | G4: 50.247654 | H4: 49.26534 | I4: 51.057763 | J4: 46.325322 | K4: 45.542841 | L4: 48.03432 | M4: 48.123897 | N4: 53.916528 | O4: =AVERAGE(D4:N4) -> 48.664576 | Q4: =(('Mode 0'!O4)/(O4)) -> 0.98139666 | R4: =_xlfn.PERCENTOF(Q4,C4)*100 -> 98.139666
A6: 512 | B6: 4 | C6: 2 | E6: 0.12237 | F6: 0.121651 | G6: 0.120366 | H6: 0.118112 | I6: 0.125569 | J6: 0.128924 | K6: 0.118485 | L6: 0.120305 | M6: 0.123536 | N6: 0.117979 | O6: =AVERAGE(D6:N6) -> 0.1217297 | Q6: =(('Mode 0'!O2)/(O6)) -> 1.8968066 | R6: =_xlfn.PERCENTOF(Q6,C6)*100 -> 94.840331
A7: 1024 | B7: 4 | C7: 2 | E7: 0.994618 | F7: 1.006189 | G7: 0.989488 | H7: 1.00497 | I7: 1.008189 | J7: 0.990748 | K7: 0.993905 | L7: 0.994416 | M7: 1.01143 | N7: 0.972499 | O7: =AVERAGE(D7:N7) -> 0.9966452 | Q7: =(('Mode 0'!O3)/(O7)) -> 1.8594367 | R7: =_xlfn.PERCENTOF(Q7,C7)*100 -> 92.971837
A8: 2048 | B8: 4 | C8: 2 | E8: 27.285417 | F8: 29.009482 | G8: 28.247238 | H8: 27.638578 | I8: 27.743897 | J8: 27.808237 | K8: 28.808304 | L8: 30.034254 | M8: 30.104631 | N8: 27.521905 | O8: =AVERAGE(D8:N8) -> 28.420194 | Q8: =(('Mode 0'!O4)/(O8)) -> 1.6804689 | R8: =_xlfn.PERCENTOF(Q8,C8)*100 -> 84.023444
A10: 512 | B10: 4 | C10: 4 | E10: 0.061905 | F10: 0.066412 | G10: 0.065564 | H10: 0.064853 | I10: 0.060759 | J10: 0.064551 | K10: 0.064156 | L10: 0.06403 | M10: 0.066239 | N10: 0.062683 | O10: =AVERAGE(D10:N10) -> 0.0641152 | Q10: =(('Mode 0'!O2)/(O10)) -> 3.6012942 | R10: =_xlfn.PERCENTOF(Q10,C10)*100 -> 90.032356
A11: 1024 | B11: 4 | C11: 4 | E11: 0.507717 | F11: 0.509122 | G11: 0.510618 | H11: 0.50675 | I11: 0.515245 | J11: 0.509584 | K11: 0.513733 | L11: 0.511493 | M11: 0.500563 | N11: 0.5088 | O11: =AVERAGE(D11:N11) -> 0.5093625 | Q11: =(('Mode 0'!O3)/(O11)) -> 3.6382708 | R11: =_xlfn.PERCENTOF(Q11,C11)*100 -> 90.956769
A12: 2048 | B12: 4 | C12: 4 | E12: 10.896129 | F12: 11.277921 | G12: 10.987101 | H12: 10.876581 | I12: 10.860759 | J12: 11.265751 | K12: 11.143477 | L12: 11.404076 | M12: 11.12137 | N12: 12.058928 | O12: =AVERAGE(D12:N12) -> 11.189209 | Q12: =(('Mode 0'!O4)/(O12)) -> 4.2683313 | R12: =_xlfn.PERCENTOF(Q12,C12)*100 -> 106.70828
A14: 512 | B14: 4 | C14: 8 | E14: 0.034146 | F14: 0.033567 | G14: 0.03528 | H14: 0.034517 | I14: 0.036205 | J14: 0.035893 | K14: 0.034036 | L14: 0.033753 | M14: 0.033424 | N14: 0.03777 | O14: =AVERAGE(D14:N14) -> 0.0348591 | Q14: =(('Mode 0'!O2)/(O14)) -> 6.6237424 | R14: =_xlfn.PERCENTOF(Q14,C14)*100 -> 82.79678
A15: 1024 | B15: 4 | C15: 8 | E15: 0.27841 | F15: 0.266303 | G15: 0.271173 | H15: 0.271592 | I15: 0.273044 | J15: 0.271962 | K15: 0.269533 | L15: 0.26454 | M15: 0.269436 | N15: 0.270124 | O15: =AVERAGE(D15:N15) -> 0.2706117 | Q15: =(('Mode 0'!O3)/(O15)) -> 6.8481839 | R15: =_xlfn.PERCENTOF(Q15,C15)*100 -> 85.602299
A16: 2048 | B16: 4 | C16: 8 | E16: 5.297239 | F16: 5.236864 | G16: 5.30151 | H16: 5.246976 | I16: 5.065996 | J16: 5.691384 | K16: 5.099631 | L16: 5.393826 | M16: 5.55896 | N16: 5.207142 | O16: =AVERAGE(D16:N16) -> 5.3099528 | Q16: =(('Mode 0'!O4)/(O16)) -> 8.9942894 | R16: =_xlfn.PERCENTOF(Q16,C16)*100 -> 112.42862
A18: 512 | B18: 4 | C18: 12 | E18: 0.025951 | F18: 0.025566 | G18: 0.026239 | H18: 0.025744 | I18: 0.027331 | J18: 0.025527 | K18: 0.02588 | L18: 0.025021 | M18: 0.025532 | N18: 0.025367 | O18: =AVERAGE(D18:N18) -> 0.0258158 | Q18: =(('Mode 0'!O2)/(O18)) -> 8.9440459 | R18: =_xlfn.PERCENTOF(Q18,C18)*100 -> 74.533716
A19: 1024 | B19: 4 | C19: 12 | E19: 0.234384 | F19: 0.241278 | G19: 0.236763 | H19: 0.23579 | I19: 0.239214 | J19: 0.240502 | K19: 0.243012 | L19: 0.24069 | M19: 0.240659 | N19: 0.238038 | O19: =AVERAGE(D19:N19) -> 0.239033 | Q19: =(('Mode 0'!O3)/(O19)) -> 7.752899 | R19: =_xlfn.PERCENTOF(Q19,C19)*100 -> 64.607491
A20: 2048 | B20: 4 | C20: 12 | E20: 4.693861 | F20: 4.712458 | G20: 4.563154 | H20: 4.554136 | I20: 4.322189 | J20: 4.468912 | K20: 4.398403 | L20: 4.333107 | M20: 4.399288 | N20: 4.501684 | O20: =AVERAGE(D20:N20) -> 4.4947192 | Q20: =(('Mode 0'!O4)/(O20)) -> 10.625636 | R20: =_xlfn.PERCENTOF(Q20,C20)*100 -> 88.54697
A22: 512 | B22: 4 | C22: 16 | E22: 0.019115 | F22: 0.019137 | G22: 0.020083 | H22: 0.019536 | I22: 0.020066 | J22: 0.019947 | K22: 0.020261 | L22: 0.020457 | M22: 0.019592 | N22: 0.019355 | O22: =AVERAGE(D22:N22) -> 0.0197549 | Q22: =(('Mode 0'!O2)/(O22)) -> 11.688123 | R22: =_xlfn.PERCENTOF(Q22,C22)*100 -> 73.050768
A23: 1024 | B23: 4 | C23: 16 | E23: 0.180511 | F23: 0.183566 | G23: 0.17866 | H23: 0.216359 | I23: 0.18713 | J23: 0.208826 | K23: 0.204799 | L23: 0.188016 | M23: 0.19207 | N23: 0.197031 | O23: =AVERAGE(D23:N23) -> 0.1936968 | Q23: =(('Mode 0'!O3)/(O23)) -> 9.5675236 | R23: =_xlfn.PERCENTOF(Q23,C23)*100 -> 59.797022
A24: 2048 | B24: 4 | C24: 16 | E24: 3.727542 | F24: 3.706658 | G24: 4.061362 | H24: 3.65661 | I24: 3.726475 | J24: 3.744701 | K24: 3.69372 | L24: 4.056487 | M24: 4.467551 | N24: 3.706255 | O24: =AVERAGE(D24:N24) -> 3.8547361 | Q24: =(('Mode 0'!O4)/(O24)) -> 12.389759 | R24: =_xlfn.PERCENTOF(Q24,C24)*100 -> 77.435995
A26: 512 | B26: 4 | C26: 20 | E26: 0.016666 | F26: 0.016677 | G26: 0.021676 | H26: 0.019133 | I26: 0.021543 | J26: 0.023783 | K26: 0.016442 | L26: 0.019685 | M26: 0.016091 | N26: 0.017006 | O26: =AVERAGE(D26:N26) -> 0.0188702 | Q26: =(('Mode 0'!O2)/(O26)) -> 12.236102 | R26: =_xlfn.PERCENTOF(Q26,C26)*100 -> 61.180512
A27: 1024 | B27: 4 | C27: 20 | E27: 0.222992 | F27: 0.180166 | G27: 0.184909 | H27: 0.192042 | I27: 0.172867 | J27: 0.178979 | K27: 0.209534 | L27: 0.181055 | M27: 0.186786 | N27: 0.178736 | O27: =AVERAGE(D27:N27) -> 0.1888066 | Q27: =(('Mode 0'!O3)/(O27)) -> 9.815328 | R27: =_xlfn.PERCENTOF(Q27,C27)*100 -> 49.07664
A28: 2048 | B28: 4 | C28: 20 | E28: 3.865492 | F28: 3.993163 | G28: 3.835642 | H28: 4.019405 | I28: 3.694856 | J28: 3.734745 | K28: 4.279829 | L28: 3.863851 | M28: 4.276839 | N28: 4.111309 | O28: =AVERAGE(D28:N28) -> 3.9675131 | Q28: =(('Mode 0'!O4)/(O28)) -> 12.037579 | R28: =_xlfn.PERCENTOF(Q28,C28)*100 -> 60.187895

Sheet Mode 5
A1: N | B1: Mode | C1: Threads | D1: Schedule | E1: Time 1 | F1: Time 2 | G1: Time 3 | H1: Time 4 | I1: Time 5 | J1: Time 6 | K1: Time 7 | L1: Time 8 | M1: Time 9 | N1: Time 10 | O1: AverageTime | Q1: Speedup | R1: Efficiency (%)
A2: 512 | B2: 5 | C2: 1 | E2: 0.226772 | F2: 0.225747 | G2: 0.22046 | H2: 0.226287 | I2: 0.2295 | J2: 0.223387 | K2: 0.227184 | L2: 0.232977 | M2: 0.230629 | N2: 0.232009 | O2: =AVERAGE(D2:N2) -> 0.2274952 | Q2: =(('Mode 0'!O2)/(O2)) -> 1.0149564 | R2: =_xlfn.PERCENTOF(Q2,C2)*100 -> 101.49564
A3: 1024 | B3: 5 | C3: 1 | E3: 1.866936 | F3: 1.868509 | G3: 1.840687 | H3: 1.833431 | I3: 1.870625 | J3: 1.836323 | K3: 1.870044 | L3: 1.873831 | M3: 1.884283 | N3: 1.933189 | O3: =AVERAGE(D3:N3) -> 1.8677858 | Q3: =(('Mode 0'!O3)/(O3)) -> 0.99219016 | R3: =_xlfn.PERCENTOF(Q3,C3)*100 -> 99.219016
A4: 2048 | B4: 5 | C4: 1 | E4: 48.116159 | F4: 46.223405 | G4: 48.975897 | H4: 49.197111 | I4: 45.81391 | J4: 48.081179 | K4: 46.632037 | L4: 48.314695 | M4: 47.170997 | N4: 48.325132 | O4: =AVERAGE(D4:N4) -> 47.685052 | Q4: =(('Mode 0'!O4)/(O4)) -> 1.001556 | R4: =_xlfn.PERCENTOF(Q4,C4)*100 -> 100.1556

Sheet Mode 6
A1: N | B1: Mode | C1: Threads | D1: Schedule | E1: Time 1 | F1: Time 2 | G1: Time 3 | H1: Time 4 | I1: Time 5 | J1: Time 6 | K1: Time 7 | L1: Time 8 | M1: Time 9 | N1: Time 10 | O1: AverageTime | Q1: Speedup | R1: Efficiency (%)
A2: 512 | B2: 6 | C2: 1 | E2: 0.225829 | F2: 0.224551 | G2: 0.233325 | H2: 0.222982 | I2: 0.230041 | J2: 0.228996 | K2: 0.222287 | L2: 0.227713 | M2: 0.229496 | N2: 0.227762 | O2: =AVERAGE(D2:N2) -> 0.2272982 | Q2: =(('Mode 0'!O2)/(O2)) -> 1.015836 | R2: =_xlfn.PERCENTOF(Q2,C2)*100 -> 101.5836
A3: 1024 | B3: 6 | C3: 1 | E3: 1.84755 | F3: 1.861376 | G3: 1.838085 | H3: 1.860944 | I3: 1.850823 | J3: 1.866397 | K3: 1.844597 | L3: 1.847819 | M3: 1.856192 | N3: 1.8591 | O3: =AVERAGE(D3:N3) -> 1.8532883 | Q3: =(('Mode 0'!O3)/(O3)) -> 0.99995165 | R3: =_xlfn.PERCENTOF(Q3,C3)*100 -> 99.995165
A4: 2048 | B4: 6 | C4: 1 | E4: 47.390674 | F4: 44.823468 | G4: 48.037209 | H4: 49.044879 | I4: 47.094407 | J4: 45.804589 | K4: 46.002005 | L4: 48.72508 | M4: 49.805203 | N4: 47.443021 | O4: =AVERAGE(D4:N4) -> 47.417054 | Q4: =(('Mode 0'!O4)/(O4)) -> 1.0072168 | R4: =_xlfn.PERCENTOF(Q4,C4)*100 -> 100.72168
A6: 512 | B6: 6 | C6: 2 | E6: 0.123718 | F6: 0.119336 | G6: 0.122076 | H6: 0.125913 | I6: 0.124116 | J6: 0.124116 | K6: 0.120451 | L6: 0.116972 | M6: 0.124566 | N6: 0.118381 | O6: =AVERAGE(D6:N6) -> 0.1219645 | Q6: =(('Mode 0'!O2)/(O6)) -> 1.893155 | R6: =_xlfn.PERCENTOF(Q6,C6)*100 -> 94.657749
A7: 1024 | B7: 6 | C7: 2 | E7: 0.985753 | F7: 1.007888 | G7: 0.997897 | H7: 0.98949 | I7: 1.016419 | J7: 0.998436 | K7: 1.014925 | L7: 1.012546 | M7: 0.985582 | N7: 0.996199 | O7: =AVERAGE(D7:N7) -> 1.0005135 | Q7: =(('Mode 0'!O3)/(O7)) -> 1.8522476 | R7: =_xlfn.PERCENTOF(Q7,C7)*100 -> 92.612379
A8: 2048 | B8: 6 | C8: 2 | E8: 30.316926 | F8: 28.972998 | G8: 30.024811 | H8: 29.338388 | I8: 29.930357 | J8: 27.433906 | K8: 30.573417 | L8: 28.16426 | M8: 27.874473 | N8: 27.43797 | O8: =AVERAGE(D8:N8) -> 29.006751 | Q8: =(('Mode 0'!O4)/(O8)) -> 1.6464875 | R8: =_xlfn.PERCENTOF(Q8,C8)*100 -> 82.324375
A10: 512 | B10: 6 | C10: 4 | E10: 0.066437 | F10: 0.072618 | G10: 0.069232 | H10: 0.066319 | I10: 0.070668 | J10: 0.067995 | K10: 0.064905 | L10: 0.065649 | M10: 0.063387 | N10: 0.063903 | O10: =AVERAGE(D10:N10) -> 0.0671113 | Q10: =(('Mode 0'!O2)/(O10)) -> 3.440519 | R10: =_xlfn.PERCENTOF(Q10,C10)*100 -> 86.012974
A11: 1024 | B11: 6 | C11: 4 | E11: 0.532442 | F11: 0.529488 | G11: 0.531664 | H11: 0.530616 | I11: 0.525045 | J11: 0.523394 | K11: 0.5319 | L11: 0.530522 | M11: 0.51927 | N11: 0.527735 | O11: =AVERAGE(D11:N11) -> 0.5282076 | Q11: =(('Mode 0'!O3)/(O11)) -> 3.5084666 | R11: =_xlfn.PERCENTOF(Q11,C11)*100 -> 87.711664
A12: 2048 | B12: 6 | C12: 4 | E12: 10.400332 | F12: 11.249809 | G12: 10.933913 | H12: 10.952636 | I12: 10.950134 | J12: 10.938138 | K12: 11.282236 | L12: 10.717108 | M12: 11.105794 | N12: 10.552615 | O12: =AVERAGE(D12:N12) -> 10.908271 | Q12: =(('Mode 0'!O4)/(O12)) -> 4.3782603 | R12: =_xlfn.PERCENTOF(Q12,C12)*100 -> 109.45651
A14: 512 | B14: 6 | C14: 8 | E14: 0.034813 | F14: 0.045798 | G14: 0.041786 | H14: 0.052028 | I14: 0.056383 | J14: 0.039593 | K14: 0.044217 | L14: 0.047652 | M14: 0.035227 | N14: 0.03814 | O14: =AVERAGE(D14:N14) -> 0.0435637 | Q14: =(('Mode 0'!O2)/(O14)) -> 5.3002316 | R14: =_xlfn.PERCENTOF(Q14,C14)*100 -> 66.252895
A15: 1024 | B15: 6 | C15: 8 | E15: 0.279531 | F15: 0.274471 | G15: 0.278354 | H15: 0.289542 | I15: 0.280482 | J15: 0.279545 | K15: 0.283829 | L15: 0.283875 | M15: 0.279348 | N15: 0.29115 | O15: =AVERAGE(D15:N15) -> 0.2820127 | Q15: =(('Mode 0'!O3)/(O15)) -> 6.5713307 | R15: =_xlfn.PERCENTOF(Q15,C15)*100 -> 82.141633
A16: 2048 | B16: 6 | C16: 8 | E16: 5.083056 | F16: 5.354164 | G16: 5.308233 | H16: 5.324343 | I16: 5.152502 | J16: 4.962761 | K16: 5.113281 | L16: 5.25221 | M16: 6.509661 | N16: 5.465191 | O16: =AVERAGE(D16:N16) -> 5.3525402 | Q16: =(('Mode 0'!O4)/(O16)) -> 8.9227265 | R16: =_xlfn.PERCENTOF(Q16,C16)*100 -> 111.53408
A18: 512 | B18: 6 | C18: 12 | E18: 0.030231 | F18: 0.033362 | G18: 0.028461 | H18: 0.030975 | I18: 0.033065 | J18: 0.035078 | K18: 0.035206 | L18: 0.034175 | M18: 0.03273 | N18: 0.033543 | O18: =AVERAGE(D18:N18) -> 0.0326826 | Q18: =(('Mode 0'!O2)/(O18)) -> 7.064851 | R18: =_xlfn.PERCENTOF(Q18,C18)*100 -> 58.873759
A19: 1024 | B19: 6 | C19: 12 | E19: 0.304934 | F19: 0.300708 | G19: 0.304248 | H19: 0.315339 | I19: 0.300619 | J19: 0.29714 | K19: 0.305128 | L19: 0.313018 | M19: 0.295798 | N19: 0.306733 | O19: =AVERAGE(D19:N19) -> 0.3043665 | Q19: =(('Mode 0'!O3)/(O19)) -> 6.0887079 | R19: =_xlfn.PERCENTOF(Q19,C19)*100 -> 50.739232
A20: 2048 | B20: 6 | C20: 12 | E20: 5.42018 | F20: 5.315691 | G20: 5.389907 | H20: 5.523553 | I20: 5.95517 | J20: 5.547675 | K20: 5.222121 | L20: 5.382465 | M20: 5.180808 | N20: 5.356725 | O20: =AVERAGE(D20:N20) -> 5.4294295 | Q20: =(('Mode 0'!O4)/(O20)) -> 8.7963666 | R20: =_xlfn.PERCENTOF(Q20,C20)*100 -> 73.303055
A22: 512 | B22: 6 | C22: 16 | E22: 0.026864 | F22: 0.021372 | G22: 0.02648 | H22: 0.025619 | I22: 0.025376 | J22: 0.02119 | K22: 0.023926 | L22: 0.022603 | M22: 0.029595 | N22: 0.025875 | O22: =AVERAGE(D22:N22) -> 0.02489 | Q22: =(('Mode 0'!O2)/(O22)) -> 9.2767256 | R22: =_xlfn.PERCENTOF(Q22,C22)*100 -> 57.979535
A23: 1024 | B23: 6 | C23: 16 | E23: 0.248228 | F23: 0.24609 | G23: 0.25668 | H23: 0.244499 | I23: 0.249713 | J23: 0.251717 | K23: 0.239451 | L23: 0.247648 | M23: 0.25633 | N23: 0.251675 | O23: =AVERAGE(D23:N23) -> 0.2492031 | Q23: =(('Mode 0'!O3)/(O23)) -> 7.4364994 | R23: =_xlfn.PERCENTOF(Q23,C23)*100 -> 46.478121
A24: 2048 | B24: 6 | C24: 16 | E24: 4.090776 | F24: 4.463532 | G24: 4.390244 | H24: 4.336442 | I24: 4.332296 | J24: 4.216578 | K24: 4.192239 | L24: 4.192239 | M24: 4.180463 | N24: 4.327743 | O24: =AVERAGE(D24:N24) -> 4.2722552 | Q24: =(('Mode 0'!O4)/(O24)) -> 11.178932 | R24: =_xlfn.PERCENTOF(Q24,C24)*100 -> 69.868328
A26: 512 | B26: 6 | C26: 20 | E26: 0.018801 | F26: 0.021401 | G26: 0.027397 | H26: 0.023322 | I26: 0.022753 | J26: 0.021941 | K26: 0.021812 | L26: 0.024676 | M26: 0.029047 | N26: 0.020511 | O26: =AVERAGE(D26:N26) -> 0.0231661 | Q26: =(('Mode 0'!O2)/(O26)) -> 9.967051 | R26: =_xlfn.PERCENTOF(Q26,C26)*100 -> 49.835255
A27: 1024 | B27: 6 | C27: 20 | E27: 0.223649 | F27: 0.227433 | G27: 0.230601 | H27: 0.230845 | I27: 0.222265 | J27: 0.222779 | K27: 0.232436 | L27: 0.222224 | M27: 0.225458 | N27: 0.23238 | O27: =AVERAGE(D27:N27) -> 0.227007 | Q27: =(('Mode 0'!O3)/(O27)) -> 8.1636192 | R27: =_xlfn.PERCENTOF(Q27,C27)*100 -> 40.818096
A28: 2048 | B28: 6 | C28: 20 | E28: 3.847792 | F28: 4.042771 | G28: 3.732878 | H28: 3.674099 | I28: 3.787794 | J28: 3.927524 | K28: 3.866387 | L28: 3.873891 | M28: 3.844958 | N28: 4.082989 | O28: =AVERAGE(D28:N28) -> 3.8681083 | Q28: =(('Mode 0'!O4)/(O28)) -> 12.346927 | R28: =_xlfn.PERCENTOF(Q28,C28)*100 -> 61.734637
